# 什么是异常

异常就是程序运行时发生错误的信号（在程序出现错误时，则会产生一个异常，若程序没有处理它，则会抛出该异常，程序的运行也随之终止），在python中，错误触发的异常如下
![](https://github.com/axin66/python/blob/59df5e3a5dd9131b85225ab67dfe165ab0b4d116/python%E5%9F%BA%E7%A1%80/%E5%9B%BE%E7%89%87/%E5%9B%BE%E7%89%875.jpg)

## 语法错误


```python
# 语法错误示范一
if

# 语法错误示范二
def test:
    pass

# 语法错误示范三
class Foo
    pass

# 语法错误示范四
print(haha
```

##  逻辑错误


```python
# TypeError:int类型不可迭代
for i in 3:
    pass

# ValueError
num=input(">>: ") #输入hello
int(num)

# NameError
aaa

# IndexError
l=['egon','aa']
l[3]

# KeyError
dic={'name':'egon'}
dic['age']

# AttributeError
class Foo:pass
Foo.x

# ZeroDivisionError:无法完成计算
res1=1/0
res2=1+'str'
```

# 异常的种类

在python中不同的异常可以用不同的类型（python中统一了类与类型，类型即类）去标识，**一个异常标识一种错误。**


## 常用异常

AttributeError 试图访问一个对象没有的树形，比如foo.x，但是foo没有属性x

IOError 输入/输出异常；基本上是无法打开文件

ImportError 无法引入模块或包；基本上是路径问题或名称错误

IndentationError 语法错误（的子类） ；代码没有正确对齐

IndexError 下标索引超出序列边界，比如当x只有三个元素，却试图访问x[5]

KeyError 试图访问字典里不存在的键

KeyboardInterrupt Ctrl+C被按下

NameError 使用一个还未被赋予对象的变量

SyntaxError Python代码非法，代码不能编译(个人认为这是语法错误，写错了）
                              
TypeError 传入对象类型与要求的不符合
                              
UnboundLocalError 试图访问一个还未被设置的局部变量，基本上是由于另有一个同名的全局变量，导致你以为正在访问它
                              
ValueError 传入一个调用者不期望的值，即使值的类型是正确的

# 异常处理

为了保证程序的健壮性与容错性，即在遇到错误时程序不会崩溃，我们需要对异常进行处理


## 提前预防

如果错误发生的条件是可预知的，我们需要用if进行处理：在错误发生之前进行预防


```python
AGE = 10
while True:
    age = input('>>: ').strip()
    if age.isdigit():  # 只有在age为字符串形式的整数时，下列代码才不会出错，该条件是可预知的
        age = int(age)
        if age == AGE:
            print('you got it')
            break
```

    >>: jack
    >>: asda
    >>: 18
    >>: 10
    you got it
    

## 之后预防

如果错误发生的条件是不可预知的，则需要用到**try...except：**在错误发生之后进行处理



```python
#基本语法为
try:
    被检测的代码块
except 异常类型：
    try中一旦检测到异常，就执行这个位置的逻辑
```


```python
#  举例
try:
    f = [
        'a',
        'a',
        'a',
        'a',
        'a',
        'a',
        'a',
    ]
    g = (line.strip() for line in f) #Python strip() 方法用于移除字符串头尾指定的字符（默认为空格或换行符）或字符序列。
    print(next(g))
    print(next(g))
    print(next(g))
    print(next(g))
    print(next(g))
except StopIteration:
    f.close()
```

    a
    a
    a
    a
    a
    

### 异常类只能用来处理指定的异常情况，如果非指定异常则无法处理。


```python
s1 = 'hello'
try:
    int(s1)
except IndexError as e:  # 未捕获到异常，程序直接报错
    print(e)
```


    ---------------------------------------------------------------------------

    ValueError                                Traceback (most recent call last)

    Input In [6], in <cell line: 2>()
          1 s1 = 'hello'
          2 try:
    ----> 3     int(s1)
          4 except IndexError as e:  # 未捕获到异常，程序直接报错
          5     print(e)
    

    ValueError: invalid literal for int() with base 10: 'hello'



```python
#从上面可以看出来异常是ValueError，我们只需稍加修改就行了
s1 = 'hello'
try:
    int(s1)
except ValueError as e:  # 捕获到异常
    print(e)
```

    invalid literal for int() with base 10: 'hello'
    

### 多分支


```python
s1 = 'hello'
try:
    int(s1)
except IndexError as e:
    print(e)
except KeyError as e:
    print(e)
except ValueError as e:
    print(e)
```

    invalid literal for int() with base 10: 'hello'
    

### 万能异常Exception


```python
s1 = 'hello'
try:
    int(s1)
except Exception as e:
    print(e)
```

    invalid literal for int() with base 10: 'hello'
    

### 多分支异常与万能异常的区别
* 如果你想要的效果是，无论出现什么异常，我们统一丢弃，或者使用同一段代码逻辑去处理他们，那么只有一个Exception就足够了。

* 如果我们想要的效果是，对于不同的异常我们需要定制不同的处理逻辑，那就需要用到多分支了。

### 异常的最终执行


```python
s1 = 'hello'
try:
    int(s1)
except IndexError as e:
    print(e)
except KeyError as e:
    print(e)
except ValueError as e:
    print(e)
#except Exception as e:
#    print(e)
else:
    print('try内代码块没有异常则执行我')
finally:
    print('无论异常与否，都会执行该模块，通常是进行清理工作')
```

    invalid literal for int() with base 10: 'hello'
    无论异常与否，都会执行该模块，通常是进行清理工作
    

# try...except总结

把错误处理和真正的工作分开来

代码更易组织，更清晰，复杂的工作任务更容易实现；

毫无疑问，更安全了，不至于由于一些小的疏忽而使程序意外崩溃了；

# 抛出异常raise

raise：单独一个 raise。该语句引发当前上下文中捕获的异常（比如在 except 块中），或默认引发 RuntimeError 异常。

raise 异常类名称：raise 后带一个异常类名称，表示引发执行类型的异常。

raise 异常类名称(描述信息)：在引发指定类型的异常的同时，附带异常的描述信息。


```python
raise
```


    ---------------------------------------------------------------------------

    RuntimeError                              Traceback (most recent call last)

    Input In [14], in <cell line: 1>()
    ----> 1 raise
    

    RuntimeError: No active exception to reraise



```python
 raise ZeroDivisionError
```


    ---------------------------------------------------------------------------

    ZeroDivisionError                         Traceback (most recent call last)

    Input In [15], in <cell line: 1>()
    ----> 1 raise ZeroDivisionError
    

    ZeroDivisionError: 



```python
raise ZeroDivisionError("除数不能为零")
```


    ---------------------------------------------------------------------------

    ZeroDivisionError                         Traceback (most recent call last)

    Input In [16], in <cell line: 1>()
    ----> 1 raise ZeroDivisionError("除数不能为零")
    

    ZeroDivisionError: 除数不能为零


事实上，raise 语句引发的异常通常用 try except（else finally）异常处理结构来捕获并进行处理。例如：


```python
try:
    a = input("输入一个数：")
    #判断用户输入的是否为数字
    if(not a.isdigit()):
        raise ValueError("a 必须是数字")
except ValueError as e:
    print("引发异常：",repr(e))
```

    输入一个数：aa
    引发异常： ValueError('a 必须是数字')
    

可以看到，当用户输入的不是数字时，程序会进入 if 判断语句，并执行 raise 引发 ValueError 异常。但由于其位于 try 块中，因为 raise 抛出的异常会被 try 捕获，并由 except 块进行处理。

因此，虽然程序中使用了 raise 语句引发异常，但程序的执行是正常的，手动抛出的异常并不会导致程序崩溃。


```python
#自定义异常
class EgonException(BaseException):
    def __init__(self, msg):
        self.msg = msg

    def __str__(self):
        return self.msg


try:
    raise EgonException('抛出异常，类型错误')
except EgonException as e:
    print(e)
```

    抛出异常，类型错误
    
